<?xml version="1.0" ?>
<!-- =================================================================================== -->
<!-- |    This document was autogenerated by xacro from panda_softhand.urdf.xacro      | -->
<!-- |    EDITING THIS FILE BY HAND IS NOT RECOMMENDED                                 | -->
<!-- =================================================================================== -->
<robot name="panda_softhand" xmlns:controller="http://playerstage.sourceforge.net/gazebo/xmlschema/#controller" xmlns:interface="http://playerstage.sourceforge.net/gazebo/xmlschema/#interface" xmlns:sensor="http://playerstage.sourceforge.net/gazebo/xmlschema/#sensor" xmlns:xacro="http://www.ros.org/wiki/xacro">
  <material name="SoftHand/LightGrey">
    <color rgba="0.7 0.7 0.7 1.0"/>
  </material>
  <material name="SoftHand/DarkGrey">
    <color rgba="0.4 0.4 0.4 1.0"/>
  </material>
  <material name="SoftHand/Black">
    <color rgba="0.0 0.0 0.0 1.0"/>
  </material>
  <material name="SoftHand/DarkGolden">
    <color rgba="0.4 0.4 0.3 1.0"/>
  </material>
  <material name="SoftHand/Blue">
    <color rgba="0.0 0.0 0.8 0.9"/>
  </material>
  <material name="SoftHand/LightBlue">
    <color rgba="0.0 0.4 1.0 0.5"/>
  </material>
  <!-- <xacro:insert_block name="gazebo_friction_properties"/> -->
  <!-- <xacro:insert_block name="gazebo_other_properties"/> -->
  <!-- NOTE: inertia values are approximated using meshlab and only using the significant elements -->
  <!-- from http://answers.ros.org/question/11350/is-there-any-way-to-calculate-inertial-property-of-a-robot-to-simulate-it-in-gazebo/s
    One general rule of thumb I use for checking my inertia tensors is: If total mass of the rigid body is m, and the dimension of the corresponding body is d, then check to see if ixx, iyy, izz are near m*(d/2)^2.

    This is by no means correct, but a sanity check to make sure the moment of inertia are the right order of magnitudes, so the model behaves somewhat physically realistically.
    -->
  <!-- <xacro:include filename="$(find franka_description)/robots/hand.urdf.xacro" /> -->
  <!-- <link name="camera_rgb_optical_frame" />                          -->
  <!--  -->
  <!--     <joint name="camera_franka_base_joint" type="fixed">
      <origin xyz="-0.486437 0.293054 0.590508" rpy="2.2907 -1.1827 -0.5876"/>
      <parent link="camera_rgb_optical_frame"/>
      <child link="world"/>
    </joint>
 -->
  <!--      <joint name="camera_franka_base_joint" type="fixed">
      <origin xyz="-0.488733 0.296781 0.584554" rpy="2.2939 -1.1813 -0.6073"/>
      <parent link="camera_rgb_optical_frame"/>
      <child link="world"/>
    </joint>
 -->
  <!-- <joint name="camera_franka_base_joint" type="fixed"> -->
  <!-- <origin xyz="-0.452453 0.21358 0.769842" rpy="2.3080 -0.6802 -0.4552"/> -->
  <!-- <parent link="camera_rgb_optical_frame"/> -->
  <!-- <child link="world"/> -->
  <!-- </joint> -->
  <link name="world"/>
  <joint name="robot_to_world" type="fixed">
    <parent link="world"/>
    <child link="panda_link0"/>
    <origin rpy="0.0 0.0 0.0" xyz="0.0 0.0 0.0"/>
    <dynamics damping="1.0"/>
  </joint>
  <link name="panda_link0">
    <visual>
      <geometry>
        <mesh filename="meshes/link0.stl"/>
      </geometry>
    </visual>
    <collision>
      <geometry>
        <mesh filename="meshes/link0.stl"/>
      </geometry>
    </collision>
    <inertial>
      <origin rpy="0 0 0" xyz="0 0 0"/>
      <mass value="3.06"/>
      <inertia ixx="0.3" ixy="0.0" ixz="0.0" iyy="0.3" iyz="0.0" izz="0.3"/>
    </inertial>
  </link>
  <link name="panda_link1">
    <visual>
      <geometry>
        <mesh filename="meshes/link1.stl"/>
      </geometry>
    </visual>
    <collision>
      <geometry>
        <mesh filename="meshes/link1.stl"/>
      </geometry>
    </collision>
    <inertial>
      <origin rpy="0 0 0" xyz="0 0 0"/>
      <mass value="2.34"/>
      <inertia ixx="0.3" ixy="0.0" ixz="0.0" iyy="0.3" iyz="0.0" izz="0.3"/>
    </inertial>
  </link>
  <joint name="panda_joint1" type="revolute">
    <safety_controller k_position="100.0" k_velocity="40.0" soft_lower_limit="-2.8973" soft_upper_limit="2.8973"/>
    <origin rpy="0 0 0" xyz="0 0 0.333"/>
    <parent link="panda_link0"/>
    <child link="panda_link1"/>
    <axis xyz="0 0 1"/>
    <limit effort="87" lower="-2.8973" upper="2.8973" velocity="2.1750"/>
    <dynamics damping="1.0"/>
  </joint>
  <link name="panda_link2">
    <visual>
      <geometry>
        <mesh filename="meshes/link2.stl"/>
      </geometry>
    </visual>
    <collision>
      <geometry>
        <mesh filename="meshes/link2.stl"/>
      </geometry>
    </collision>
    <inertial>
      <origin rpy="0 0 0" xyz="0 0 0"/>
      <mass value="2.36"/>
      <inertia ixx="0.3" ixy="0.0" ixz="0.0" iyy="0.3" iyz="0.0" izz="0.3"/>
    </inertial>
  </link>
  <joint name="panda_joint2" type="revolute">
    <safety_controller k_position="100.0" k_velocity="40.0" soft_lower_limit="-1.7628" soft_upper_limit="1.7628"/>
    <origin rpy="-1.57079632679 0 0" xyz="0 0 0"/>
    <parent link="panda_link1"/>
    <child link="panda_link2"/>
    <axis xyz="0 0 1"/>
    <limit effort="87" lower="-1.7628" upper="1.7628" velocity="2.1750"/>
    <dynamics damping="1.0"/>
  </joint>
  <link name="panda_link3">
    <visual>
      <geometry>
        <mesh filename="meshes/link3.stl"/>
      </geometry>
    </visual>
    <collision>
      <geometry>
        <mesh filename="meshes/link3.stl"/>
      </geometry>
    </collision>
    <inertial>
      <origin rpy="0 0 0" xyz="0 0 0"/>
      <mass value="2.38"/>
      <inertia ixx="0.3" ixy="0.0" ixz="0.0" iyy="0.3" iyz="0.0" izz="0.3"/>
    </inertial>
  </link>
  <joint name="panda_joint3" type="revolute">
    <safety_controller k_position="100.0" k_velocity="40.0" soft_lower_limit="-2.8973" soft_upper_limit="2.8973"/>
    <origin rpy="1.57079632679 0 0" xyz="0 -0.316 0"/>
    <parent link="panda_link2"/>
    <child link="panda_link3"/>
    <axis xyz="0 0 1"/>
    <limit effort="87" lower="-2.8973" upper="2.8973" velocity="2.1750"/>
    <dynamics damping="1.0"/>
  </joint>
  <link name="panda_link4">
    <visual>
      <geometry>
        <mesh filename="meshes/link4.stl"/>
      </geometry>
    </visual>
    <collision>
      <geometry>
        <mesh filename="meshes/link4.stl"/>
      </geometry>
    </collision>
    <inertial>
      <origin rpy="0 0 0" xyz="0 0 0"/>
      <mass value="2.43"/>
      <inertia ixx="0.3" ixy="0.0" ixz="0.0" iyy="0.3" iyz="0.0" izz="0.3"/>
    </inertial>
  </link>
  <joint name="panda_joint4" type="revolute">
    <safety_controller k_position="100.0" k_velocity="40.0" soft_lower_limit="-3.0718" soft_upper_limit="-0.0698"/>
    <origin rpy="1.57079632679 0 0" xyz="0.0825 0 0"/>
    <parent link="panda_link3"/>
    <child link="panda_link4"/>
    <axis xyz="0 0 1"/>
    <limit effort="87" lower="-3.0718" upper="-0.0698" velocity="2.1750"/>
    <dynamics damping="1.0"/>
  </joint>
  <link name="panda_link5">
    <visual>
      <geometry>
        <mesh filename="meshes/link5.stl"/>
      </geometry>
    </visual>
    <collision>
      <geometry>
        <mesh filename="meshes/link5.stl"/>
      </geometry>
    </collision>
    <inertial>
      <origin rpy="0 0 0" xyz="0 0 0"/>
      <mass value="3.5"/>
      <inertia ixx="0.3" ixy="0.0" ixz="0.0" iyy="0.3" iyz="0.0" izz="0.3"/>
    </inertial>
  </link>
  <joint name="panda_joint5" type="revolute">
    <safety_controller k_position="100.0" k_velocity="40.0" soft_lower_limit="-2.8973" soft_upper_limit="2.8973"/>
    <origin rpy="-1.57079632679 0 0" xyz="-0.0825 0.384 0"/>
    <parent link="panda_link4"/>
    <child link="panda_link5"/>
    <axis xyz="0 0 1"/>
    <limit effort="12" lower="-2.8973" upper="2.8973" velocity="2.6100"/>
    <dynamics damping="1.0"/>
  </joint>
  <link name="panda_link6">
    <visual>
      <geometry>
        <mesh filename="meshes/link6.stl"/>
      </geometry>
    </visual>
    <collision>
      <geometry>
        <mesh filename="meshes/link6.stl"/>
      </geometry>
    </collision>
    <inertial>
      <origin rpy="0 0 0" xyz="0 0 0"/>
      <mass value="1.47"/>
      <inertia ixx="0.3" ixy="0.0" ixz="0.0" iyy="0.3" iyz="0.0" izz="0.3"/>
    </inertial>
  </link>
  <joint name="panda_joint6" type="revolute">
    <safety_controller k_position="100.0" k_velocity="40.0" soft_lower_limit="-0.0175" soft_upper_limit="3.7525"/>
    <origin rpy="1.57079632679 0 0" xyz="0 0 0"/>
    <parent link="panda_link5"/>
    <child link="panda_link6"/>
    <axis xyz="0 0 1"/>
    <limit effort="12" lower="-0.0175" upper="3.7525" velocity="2.6100"/>
    <dynamics damping="1.0"/>
  </joint>
  <link name="panda_link7">
    <visual>
      <geometry>
        <mesh filename="meshes/link7.stl"/>
      </geometry>
    </visual>
    <collision>
      <geometry>
        <mesh filename="meshes/link7.stl"/>
      </geometry>
    </collision>
    <inertial>
      <origin rpy="0 0 0" xyz="0 0 0"/>
      <mass value="0.45"/>
      <inertia ixx="0.3" ixy="0.0" ixz="0.0" iyy="0.3" iyz="0.0" izz="0.3"/>
    </inertial>
  </link>
  <joint name="panda_joint7" type="revolute">
    <safety_controller k_position="100.0" k_velocity="40.0" soft_lower_limit="-2.8973" soft_upper_limit="2.8973"/>
    <origin rpy="1.57079632679 0 0" xyz="0.088 0 0"/>
    <parent link="panda_link6"/>
    <child link="panda_link7"/>
    <axis xyz="0 0 1"/>
    <limit effort="12" lower="-2.8973" upper="2.8973" velocity="2.6100"/>
    <dynamics damping="1.0"/>
  </joint>
  <link name="panda_link8">
    <inertial>
      <origin rpy="0 0 0" xyz="0 0 0"/>
      <mass value="0.0"/>
      <inertia ixx="0.3" ixy="0.0" ixz="0.0" iyy="0.3" iyz="0.0" izz="0.3"/>
    </inertial>
  </link>
  <joint name="panda_joint8" type="fixed">
    <origin rpy="0 0 0" xyz="0 0 0.107"/>
    <parent link="panda_link7"/>
    <child link="panda_link8"/>
    <axis xyz="0 0 0"/>
  </joint>
  <joint name="panda_link8_right_hand_panda_flange_joint" type="fixed">
    <origin rpy="0.0 0.0 1.5707" xyz="0.0425 0.0 0.038"/>
    <parent link="panda_link8"/>
    <child link="right_hand_panda_flange"/>
  </joint>
  <link name="right_hand_panda_flange">
    <visual>
      <origin rpy="0 0 0" xyz="0 0 0"/>
      <geometry>
        <mesh filename="soft_hand_description/meshes/accesories/panda_flange.stl" scale="0.001 0.001 0.001"/>
      </geometry>
      <material name="SoftHand/DarkGrey"/>
    </visual>
    <collision>
      <origin rpy="0 0 0" xyz="0 0.04 -0.02"/>
      <geometry>
        <box size="0.08 0.08 0.08"/>
      </geometry>
    </collision>
  </link>
    <joint name="right_hand_panda_flange_right_hand_softhand_round_base_joint" type="fixed">
    <origin rpy="1.5707 0.0 0.0" xyz="0.0 -0.011 0.0"/>
    <parent link="right_hand_panda_flange"/>
    <child link="right_hand_softhand"/>
  </joint>
  <link name="right_hand_softhand">
    <visual>
      <origin rpy="3.14 0 0" xyz="0 0.015 0.12"/>
      <geometry>
        <mesh filename="meshes/CAD_SoftHand_Research_STL.stl" scale="0.001 0.001 0.001"/>
      </geometry>
    </visual>
    <collision>
      <origin rpy="0 0 0" xyz="0 0 0.031"/>
      <geometry>
        <box size="0.066 0.066 0.062"/>
      </geometry>
    </collision>
  </link>
  <!-- EXTRA ENDEFFECTOR -->
  <joint name="right_hand_ee_joint" type="fixed">
    <origin rpy="0 1.5708 0" xyz="0.158 0.001 0.04"/>
    <parent link="panda_link8"/>
    <child link="right_hand"/>
  </joint>
  <link name="right_hand">
  </link>
</robot>
